Traceback (most recent call last):
  File "/home/paladin/anaconda3/envs/matdata/lib/python3.11/site-packages/jupyter_core/utils/__init__.py", line 154, in wrapped
    asyncio.get_running_loop()
RuntimeError: no running event loop

During handling of the above exception, another exception occurred:

Traceback (most recent call last):
  File "/home/paladin/anaconda3/envs/matdata/lib/python3.11/site-packages/jupyter_cache/executors/utils.py", line 58, in single_nb_execution
    executenb(
  File "/home/paladin/anaconda3/envs/matdata/lib/python3.11/site-packages/nbclient/client.py", line 1319, in execute
    return NotebookClient(nb=nb, resources=resources, km=km, **kwargs).execute()
           ^^^^^^^^^^^^^^^^^^^^^^^^^^^^^^^^^^^^^^^^^^^^^^^^^^^^^^^^^^^^^^^^^^^^^
  File "/home/paladin/anaconda3/envs/matdata/lib/python3.11/site-packages/jupyter_core/utils/__init__.py", line 158, in wrapped
    return loop.run_until_complete(inner)
           ^^^^^^^^^^^^^^^^^^^^^^^^^^^^^^
  File "/home/paladin/anaconda3/envs/matdata/lib/python3.11/asyncio/base_events.py", line 654, in run_until_complete
    return future.result()
           ^^^^^^^^^^^^^^^
  File "/home/paladin/anaconda3/envs/matdata/lib/python3.11/site-packages/nbclient/client.py", line 709, in async_execute
    await self.async_execute_cell(
  File "/home/paladin/anaconda3/envs/matdata/lib/python3.11/site-packages/nbclient/client.py", line 1062, in async_execute_cell
    await self._check_raise_for_error(cell, cell_index, exec_reply)
  File "/home/paladin/anaconda3/envs/matdata/lib/python3.11/site-packages/nbclient/client.py", line 918, in _check_raise_for_error
    raise CellExecutionError.from_cell_and_msg(cell, exec_reply_content)
nbclient.exceptions.CellExecutionError: An error occurred while executing the following cell:
------------------
# Replace with your own API key! (keep the '' signs)
API_KEY = "YOUR_API_KEY_HERE"
mpr = MPRester(API_KEY)
------------------


[31m---------------------------------------------------------------------------[39m
[31mValueError[39m                                Traceback (most recent call last)
[36mCell[39m[36m [39m[32mIn[2][39m[32m, line 3[39m
[32m      1[39m [38;5;66;03m# Replace with your own API key! (keep the '' signs)[39;00m
[32m      2[39m API_KEY = [33m"[39m[33mYOUR_API_KEY_HERE[39m[33m"[39m
[32m----> [39m[32m3[39m mpr = [43mMPRester[49m[43m([49m[43mAPI_KEY[49m[43m)[49m

[36mFile [39m[32m~/anaconda3/envs/matdata/lib/python3.11/site-packages/mp_api/client/mprester.py:171[39m, in [36mMPRester.__init__[39m[34m(self, api_key, endpoint, notify_db_version, include_user_agent, monty_decode, use_document_model, session, headers, mute_progress_bars)[39m
[32m    168[39m api_key = api_key [38;5;129;01mor[39;00m os.getenv([33m"[39m[33mMP_API_KEY[39m[33m"[39m) [38;5;129;01mor[39;00m SETTINGS.get([33m"[39m[33mPMG_MAPI_KEY[39m[33m"[39m)
[32m    170[39m [38;5;28;01mif[39;00m api_key [38;5;129;01mand[39;00m [38;5;28mlen[39m(api_key) != [32m32[39m:
[32m--> [39m[32m171[39m     [38;5;28;01mraise[39;00m [38;5;167;01mValueError[39;00m(
[32m    172[39m         [33m"[39m[33mPlease use a new API key from https://materialsproject.org/api [39m[33m"[39m
[32m    173[39m         [33m"[39m[33mKeys for the new API are 32 characters, whereas keys for the legacy [39m[33m"[39m
[32m    174[39m         [33m"[39m[33mAPI are 16 characters.[39m[33m"[39m
[32m    175[39m     )
[32m    177[39m [38;5;28mself[39m.api_key = api_key
[32m    178[39m [38;5;28mself[39m.endpoint = endpoint [38;5;129;01mor[39;00m os.getenv(
[32m    179[39m     [33m"[39m[33mMP_API_ENDPOINT[39m[33m"[39m, [33m"[39m[33mhttps://api.materialsproject.org/[39m[33m"[39m
[32m    180[39m )

[31mValueError[39m: Please use a new API key from https://materialsproject.org/api Keys for the new API are 32 characters, whereas keys for the legacy API are 16 characters.

